Workbook
Name Beginning_Balance: -FV(Interest_Rate/12,Payment_Number-1,-Monthly_Payment,Loan_Amount)
Name ColumnTitle1: #REF!
Name Ending_Balance: -FV(Interest_Rate/12,Payment_Number,-Monthly_Payment,Loan_Amount)
Name Full_Print: #REF!
Name Header_Row: ROW(#REF!)
Name Header_Row_Back: ROW(#REF!)
Name Interest: -IPMT(Interest_Rate/12,Payment_Number,Number_of_Payments,Loan_Amount)
Name Interest_Rate: #REF!
Name Last_Row: IF(Values_Entered,Header_Row+Number_of_Payments,Header_Row)
Name Loan_Amount: #REF!
Name Loan_Not_Paid: IF(Payment_Number<=Number_of_Payments,1,0)
Name Loan_Start: #REF!
Name Loan_Years: #REF!
Name Monthly_Payment: -PMT(Interest_Rate/12,Number_of_Payments,Loan_Amount)
Name Number_of_Payments: #REF!
Name Payment_Date: DATE(YEAR(Loan_Start),MONTH(Loan_Start)+Payment_Number,DAY(Loan_Start))
Name Payment_Number: ROW()-Header_Row
Name Principal: -PPMT(Interest_Rate/12,Payment_Number,Number_of_Payments,Loan_Amount)
Name RowTitleRegion1..E6: #REF!
Name RowTitleRegion2..E11: #REF!
Name Total_Cost: #REF!
Name Total_Interest: #REF!
Name Values_Entered: IF(Loan_Amount*Interest_Rate*Loan_Years*Loan_Start>0,1,0)
Name Beginning_Balance: -FV(Guidance!Interest_Rate/12,Guidance!Payment_Number-1,-Guidance!Monthly_Payment,Guidance!Loan_Amount)
Name ColumnTitle1: [1]!Loan[[#Headers],[No.]]
Name Ending_Balance: -FV(Guidance!Interest_Rate/12,Guidance!Payment_Number,-Guidance!Monthly_Payment,Guidance!Loan_Amount)
Name Header_Row: ROW('[1]Loan Calculator'!$14:$14)
Name Header_Row_Back: ROW('[1]Loan Calculator'!$14:$14)
Name Interest: -IPMT(Guidance!Interest_Rate/12,Guidance!Payment_Number,Guidance!Number_of_Payments,Guidance!Loan_Amount)
Name Interest_Rate: '[1]Loan Calculator'!$E$6
Name Last_Row: IF(Guidance!Values_Entered,Guidance!Header_Row+Guidance!Number_of_Payments,Guidance!Header_Row)
Name Loan_Amount: '[1]Loan Calculator'!$E$5
Name Loan_Not_Paid: IF(Guidance!Payment_Number<=Guidance!Number_of_Payments,1,0)
Name Loan_Start: '[1]Loan Calculator'!$E$8
Name Loan_Years: '[1]Loan Calculator'!$E$7
Name Monthly_Payment: -PMT(Guidance!Interest_Rate/12,Guidance!Number_of_Payments,Guidance!Loan_Amount)
Name Number_of_Payments: '[1]Loan Calculator'!$E$11
Name Payment_Date: DATE(YEAR(Guidance!Loan_Start),MONTH(Guidance!Loan_Start)+Guidance!Payment_Number,DAY(Guidance!Loan_Start))
Name Payment_Number: ROW()-Guidance!Header_Row
Name Principal: -PPMT(Guidance!Interest_Rate/12,Guidance!Payment_Number,Guidance!Number_of_Payments,Guidance!Loan_Amount)
Name Total_Cost: '[1]Loan Calculator'!$E$13
Name Values_Entered: IF(Guidance!Loan_Amount*Guidance!Interest_Rate*Guidance!Loan_Years*Guidance!Loan_Start>0,1,0)
Name Beginning_Balance: -FV(Interest_Rate/12,'1 Business Plan(BP)'!Payment_Number-1,-'1 Business Plan(BP)'!Monthly_Payment,Loan_Amount)
Name ColumnTitle1: #REF!
Name Ending_Balance: -FV(Interest_Rate/12,'1 Business Plan(BP)'!Payment_Number,-'1 Business Plan(BP)'!Monthly_Payment,Loan_Amount)
Name Interest: -IPMT(Interest_Rate/12,'1 Business Plan(BP)'!Payment_Number,Number_of_Payments,Loan_Amount)
Name Last_Row: IF('1 Business Plan(BP)'!Values_Entered,Header_Row+Number_of_Payments,Header_Row)
Name Loan_Not_Paid: IF('1 Business Plan(BP)'!Payment_Number<=Number_of_Payments,1,0)
Name Monthly_Payment: -PMT(Interest_Rate/12,Number_of_Payments,Loan_Amount)
Name Payment_Date: DATE(YEAR(Loan_Start),MONTH(Loan_Start)+'1 Business Plan(BP)'!Payment_Number,DAY(Loan_Start))
Name Payment_Number: ROW()-Header_Row
Name Principal: -PPMT(Interest_Rate/12,'1 Business Plan(BP)'!Payment_Number,Number_of_Payments,Loan_Amount)
Name Values_Entered: IF(Loan_Amount*Interest_Rate*Loan_Years*Loan_Start>0,1,0)
Name Beginning_Balance: -FV('Loan Calculator'!Interest_Rate/12,'Loan Calculator'!Payment_Number-1,-'Loan Calculator'!Monthly_Payment,'Loan Calculator'!Loan_Amount)
Name ColumnTitle1: Loan3[[#Headers],[No.]]
Name Ending_Balance: -FV('Loan Calculator'!Interest_Rate/12,'Loan Calculator'!Payment_Number,-'Loan Calculator'!Monthly_Payment,'Loan Calculator'!Loan_Amount)
Name Full_Print: 'Loan Calculator'!$A$4:$H$262
Name Header_Row: ROW('Loan Calculator'!$26:$26)
Name Header_Row_Back: ROW('Loan Calculator'!$26:$26)
Name Interest: -IPMT('Loan Calculator'!Interest_Rate/12,'Loan Calculator'!Payment_Number,'Loan Calculator'!Number_of_Payments,'Loan Calculator'!Loan_Amount)

Sheet Months
A1: January
A2: February
A3: March
A4: April
A5: May
A6: June
A7: July
A8: August
A9: September
A10: October
A11: November
A12: December

Sheet Guidance
D3: Name: | E3: Harsha Dandi
D4: Company Name: | E4: SOLUM
B6: Guidance on using these templates for your Start Up Loan application
B7: - First, please save your name and company name to this document, using the space above - In this document, you will find four tabs, that need to be completed as part of your loan application - Don't worry if you need some help. At the top of each tab you will find both a description of each of the templates, as well as some tips on how to complete them - We suggest you complete each template in number order so that you can carry forward any of your workings - If you need some help completing these documents, you can submit them as a first draft, within the customer portal and one of our Business Support Partners will be in touch to provide further assistance - If you have already completed a Business Plan, Personal Survival Budget or Cash Flow Forecast, you do not have to transfer the information into our templates - Our templates have been designed to support our application process, so we would encourage you to provide the information we have requested across these templates, to help us assess your application quicker, so please review the information you provide before submitting - Finally, don't forget to save your document as you go through
B10: TIPS ON COMPLETING THE TEMPLATES
B12: * | C12: The templates are designed to be as easy to use as possible - for the BP tab, please follow the guidelines closely and relate these guidelines to your business. For the CFF, SA and PSB, simply enter your figures into the white coloured cells on the templates and all of the light blue coloured cells will auto-calculate based on your responses.
B13: * | C13: For an explanation of any terms included on these templates, hover over the cells that have a red triangle in the top right corner and you will see some further instructions and guidance related to that item. If you're still unsure don't worry: your first draft won't necessarily be your final submission. Your Business Adviser will be able to work with you once you have submitted an initial draft;
B14: * | C14: For the PSB and CFF, If you want to see what formula is being used to calculate any of the blue cells, or find out which cells are being used in the calculation, simply click on the cell and the formula will display in the Formula Bar at the top of the page;
B15: * | C15: If any of the numbers you enter result in a negative balance, then this negative balance will be displayed in red to draw this to your attention. Ideally, you want to avoid negative totals or balances, so think about what you can feasibly change in order to achieve this. Alternatively please provide details of how this negative balance will be covered (i.e. Business overdraft etc.) within the commentary box provided;
B16: * | C16: The templates list a range of common options but they might not all be applicable for you. Add or remove items as relevant to you and your business;
B17: * | C17: All values that you enter should be in GBP (£) and should include VAT;
B18: * | C18: Use the commentary box at the bottom of the templates to explain any assumptions you've made or notes you'd like to discuss with your Business Adviser;
B20: * | C20: For free and impartial advice on your personal budgeting, contact the government-backed Money Advice Service via their website or telephone.
C21: Go to http://www.moneyadviceservice.org.uk or call: 0800 138 7777 (calls are free).
B23: Excel Tips
B25: * | C25: If you need to go to the next line in a cell or create another bullet point in the same cell, press and hold the Alt key and click the Enter key once. This will tab down to the next line but you will remain in the same cell. To save the changes you have made to the cell, press Enter once you are finished. Do not press Esc as this will delete your changes.
B26: * | C26: If you need to edit a cell without deleting any of the text you have already typed in, first select the cell and click in the formula bar (shown in screenshot below)
B27: * | C27: If you need more help with using excel please see our Excel Tips tab
B29: Uploading this document to the portal
B31: * | C31: Once you reach Stage 3:1 in the online application process you will first be asked to provide some basic information about your business as shown below (left)
B32: * | C32: Following this, you will reach stage 3:2 where you will be asked to upload your business documents as shown below (right). You will also have the option to request help with your documents, if you need it.
C34: Stage 3:1 | J34: Stage 3:2
B60: * | C60: If you need to re-visit the portal and re-upload your documents after making amendments, you can do so at any time by logging into your account and viewing the "Your Business information and documents" section on the portal and re-uploading.

Sheet 1 Business Plan(BP)
B3: Business Plan
D4: Name: | E4: Harsha Dandi
D5: Company Name: | E5: SOLUM
B7: Your Business Plan (BP) should detail your blueprint for how your business will operate. Your Business Plan is designed to help us determine whether or not your Business is viable and can sustainably produce sufficient profits to maintain your monthly Start Up Loan repayments.
B9: - The content in the Business Plan below is the minimum requirement for completing the business viability part of your application;
B10: - Please complete each field using the questions, prompts and examples as a guideline for the detail that we require;
B11: - The closer you can follow the guidelines to complete the BP, the more likely you are to provide your assigned Business Support Partner with the information they need to make a decision;
B12: - In some instances, more information may be required. If this is the case, your Business Adviser will inform you of what further information is needed;
B13: - Please note, your BP can be a first draft, it doesn't have to be perfect. If you need more help, submit what you can and your Business Support Partner will be in touch;
B15: 1. Your business and objectives | K15: Guidance
B18: Describe your business, outlining the different product(s) and/or service(s) you offer:
B19: SOLUM is a men's premium body care brand selling structured shower ritual kits direct-to-consumer at bysolum.co.uk. Currently sole trader (LTD registration pending). Founder owns 100% of business. Not yet trading — Start Up Loan funds first inventory order. Products: 8 SKUs in a Daily Ritual (10 min) and Weekly Deep Ritual (22 min). Includes: sulphate-free amino acid body wash (UK, Cosmiko), exfoliating mitt + back cloth (Korean tradition, China manufacture), silicone scalp massager (South Korea), rhassoul clay mask + organic argan oil (Morocco), fast-absorb body lotion (UK, Cosmiko), artisan Kese mitt (Turkey). Kit tiers: GROUND (products 01,02,03,04,07) £65 first box / £38 monthly refill. RITUAL (all 7 products) £85 / £48. SOVEREIGN (all 10) £130 / £58 — coming soon. Business model: customer buys first kit (tools last 6-12 months), then subscribes to monthly consumable refills. CAC £28, LTV at 14 months £428 GP, LTV:CAC 15.3x. Monthly churn 7%. Home-based. Royal Mail Tracked 48. Key milestones: brand identity locked, website live at bysolum.co.uk, full product lineup confirmed, supplier briefs sent to Cosmiko UK, COOLFIN A Korea, Moroccan suppliers, labels + ritual card designed, CPSR compliance plan confirmed. 180 people on pre-launch waitlist — demand validated before first sale. | K19: Things to consider: - What products do you sell or what services do you provide? - What percentage of the company do you own? - Is the business already trading? - Trading Entity (Limited company, sole trader or partnership etc.) - Operational structure of business including any planned changes - for example do you have staff? if so, how many? - Will/do you have Commercial Premises or is this a home based business? - If commercial premises, please provide a head of terms, lease or storage agreement - Business performance (financially) to date if you have started trading - Key Milestones achieved (for example you have created a website) - If you have purchase orders, please provide evidence and the value of these purchase orders.
B38: Objectives:
B40: Short term (current year):
B41: 1. Complete first inventory order (250 kits) and receive stock by July 2026. Total outlay: £6,930 (COGS £6,130 + packaging £800). 2. Launch bysolum.co.uk to paying customers June/July 2026 — first sale by 30 June 2026. 3. Convert 180-person waitlist — acquire 50 active subscribers by 30 Sep 2026, generating £1,900/month recurring revenue. 4. Complete CPSR compliance for all 4 cosmetic products (01,05,06,07) and submit SCPN notification via UK Submit by 31 July 2026. | K41: Objectives should be SMART: Specific, Measurable, Attainable, Realistic and Time bound Examples: Develop a website that is transaction based so customers can place orders by 01/011/2021 Create a customer relationship management framework by 01/12/2021 Reduce direct costs by 20% negotiating a better deal with suppliers based on higher purchase volumes by 01/12/2021
B48: Medium term (next 1 – 2 years):
B49: 1. Reach 405 active subscribers by May 2027 (12 months trading), generating £17,010/month MRR — in line with conservative Year 1 projections. 2. Scale total revenue to £324,000+ in Year 2 (2027) — 60% annual growth on new customer acquisition. 3. Launch SOVEREIGN tier (products 09+10: Turkish Kese mitt and Black Soap) by Q2 2027. 4. Reduce effective CAC to under £25 by Q2 2027 through organic Instagram content driving 35%+ of new customers without paid spend. | K49: Objectives should be SMART: Specific, Measurable, Attainable, Realistic and Time bound Examples: Increase revenue by 5% each of the next 4 quarters Use suggestive selling to increase the total value of each sale by 10 percent by the end of the current fiscal year. Send a service quality survey to every customer within 30 days of their first contact.
B56: Your Start Up Loan:
B58: Describe how you will use your Start Up Loan and how it will help you achieve these objectives:
B59: Cost Description | E59: Cost (£) | F59: Rationale | K59: Things to consider: - Is all your expenditure needed at the outset? Please consider your total funding requirement over the first 12 month trading period - Please could you provide a full and detailed loan breakdown? This needs to be very specific. Like a shopping list, please provide details of each item with a £ value alongside each item. The more specific and detailed you are, the more likely you will be successful. Please provide a brief description of why each item would be useful for the business. Please see some examples below. - Equipment purchase £3000 total. £2000 for a large pressure washer and £1000 for a small pressure washer. - Working capital - surplus of stock. For example, paying creditors - The loan will be used as a Lease deposit - Staff changes - Change of premises - The loan will be used to fulfil purchase orders
B60: Cosmiko UK — Body Wash (Product 01) high-MOQ order | E60: 8000 | F60: ~2,500 units at improved MOQ pricing (standard 250-unit price is £3.20/unit). Larger order unlocks Cosmiko volume discount. Covers 12+ months of body wash demand.
B61: Cosmiko UK — Body Lotion (Product 07) high-MOQ order | E61: 8000 | F61: ~1,800 units at improved pricing. Combined with body wash, unlocks best pricing tier. Lotion is in every kit and every monthly refill — highest reorder frequency product.
B62: Morocco — Clay Mask (P05) + Argan Oil (P06) | E62: 4500 | F62: ~500 units clay mask (£3.50/unit) + ~500 units argan oil (£5.50/unit). Fatima's Garden MOQ is only 12 — this order builds a 12+ month stock position.
B63: Korea/China — Exfoliating Mitt (P02), Back Cloth (P03), Scalp Massager (P04) | E63: 2000 | F63: ~500 units each. Mitt £0.42, back cloth £0.80, scalp massager £2.00. Tools in first kits only, not monthly refills — stock lasts longer.
B64: Turkey — Kese Mitt (P09) — Jennifer's Hamam, artisan hand-woven | E64: 1500 | F64: ~250-300 units at £4.50-£6.00/unit. MOQ 30-50. SOVEREIGN tier + premium upsell.
B65: Packaging — first 500 kits (boxes, ritual cards, tissue, mailers) | E65: 1000 | F65: Matte black magnetic boxes, tissue, steel blue ribbon, 400gsm ritual cards, mailers.
B73: 2. Your skills and experience
B76: Outline any previous experience, employment or other work that you have done that is relevant to your business:
B77: 20+ years experience in banking and technology, building trading systems and large-scale enterprise applications for financial institutions. Currently employed at Meta (Facebook), where I have direct experience scaling digital products to hundreds of millions of users, building automated technical systems, and deploying paid social advertising at scale — the primary channel SOLUM will use. I am building SOLUM for myself. As the exact target customer, I have direct insight into the market gap. My Meta background gives a significant competitive advantage in running efficient paid social campaigns. My 20+ years in financial services provides commercial acumen, financial modelling capability, and supplier management discipline. All e-commerce, subscription billing, and automation systems can be built in-house — no agencies in Year 1. | K77: You may have: Previously set up another business / a similar business. Previously worked in the same sector for another business. Had formal training / qualifications Is there any training required that you do not have? Personal traits that make you well suited to run the company (natural salesman, well organised, language, creative, analytical etc.).
B84: Outline any education or training you have had that is relevant to your business:
B85: Master's degree in Computer Science. Provides strong foundation in systems thinking, analytical problem-solving, and technology implementation — directly supporting SOLUM's digital-first, data-driven approach to customer acquisition and subscription management. | K85: Depending on the business, you may be required to have certain qualifications/training and if so, please make the details of when/how these were achieved clear. For example "I have a Level 3 NVQ Diploma in Domestic Plumbing and heating which I achieved in August 2010." Or "I have a degree in Business Management with Open University"
B94: 3. Your target customers | L94: Guidance
B97: Demographic details:
B98: Briefly describe your target customers:
B99: Primary: Men aged 25-45, UK-based, household income £35,000+. Engaged in fitness/sport. Already spend on some grooming products but have no structured body care system. Comfortable with DTC online purchasing and subscriptions. Secondary: Gift-buyers (partners, parents) for men 25-45. Also men who already spend on premium grooming (Bulldog, Patricks, Hims) but want a more complete system. Geographic: UK-wide, primarily England. All sales via bysolum.co.uk in Year 1. | L99: Look at your current customer base. Analse your product/service. Choose specific demographics to target. Consider the psychographics of your target. Evaluate your decision.
B105: What customer need or problem does your product(s) and/or service(s) address?
B106: Most men shower daily and still have rough skin, a neglected back, and a scalp never properly cleaned. No brand has built a complete, sequenced body care system for men. Every men's grooming brand focuses on face, hair, or fragrance. SOLUM delivers a specific daily and weekly ritual in a single box: the right tools, the right formulations, step-by-step instructions. The system is complete on arrival.
B112: Explain your approach to pricing your product(s) and/or service(s):
B113: Positioned premium-accessible — above mass market (Bulldog, Simple) but below luxury (Aesop, Noble Isle). Pricing justified by ingredient provenance (Moroccan organic argan, Korean bathhouse technique, UK amino acid wash) and system value — customers buy a complete ritual. GROUND Kit £65 first box (69% GM), RITUAL Kit £85 (70% GM). Monthly refills £38-£48 (48-64% GM). Benchmark: Bulldog kits £20-35 (mass, face only). Patricks £25-55/item (premium, hair focused). SOLUM: only complete body ritual kit at one accessible price.
B121: 4. Your market and competition | L121: Guidance
...

Sheet Loan Calculator
B3: Loan calculator
B5: INSTRUCTIONS Only complete fields E10, E12 and E13. If you have a Capital Repayment Holiday, complete the Capital Repayment section. 1. Fill in loan value 2. Fill in loan term 3. All other fields will automatically populate 4. Scroll down to the table below to see the repayments after the CRH. 5. Go to the CFF (tab below) 6. Loan repayment row on the CFF has been automatically populated.
B10: Key:
B16: Enter values | G16: Capital Repayment Holiday
B17: Loan amount | E17: 7000 | G17: Do you have a CRH?
B18: Annual interest rate | E18: 0.075 | G18: No | K18: Yes
B19: Loan period in months | E19: 60 | G19: =IF(ISBLANK(G18),"",IF(G18="Yes","Length of CRH (Months)","Please enter loan values")) | K19: No
B20: =IF(G18="Yes","Start date of loan after CRH","Start date of loan") | E20: 44145 | G20: 6
B21: Monthly payment | E21: =IFERROR(IF(Values_Entered,Monthly_Payment,""), "") | G21: =IF(ISBLANK(G20),"","Start date of loan")
B22: Number of payments | E22: =IFERROR(IF(Values_Entered,Loan_Years,""), "") | G22: 46099
B23: Total interest | E23: =IFERROR(IF(Values_Entered,Total_Cost-Loan_Amount,""), "") | G23: Payment for CRH Period
B24: Total cost of loan | E24: =IFERROR(IF(Values_Entered,Monthly_Payment*Number_of_Payments,""), "") | G24: =IF(ISBLANK(G20),"",G27)
B26: No. | C26: Payment Date | D26: Beginning Balance | E26: Payment | F26: Principal | G26: Interest | H26: Ending Balance
B27: =IFERROR(IF(Loan_Not_Paid*Values_Entered,Payment_Number,""), "") | C27: =IFERROR(IF(Loan_Not_Paid*Values_Entered,Payment_Date,""), "") | D27: =IFERROR(IF(Loan_Not_Paid*Values_Entered,Beginning_Balance,""), "") | E27: =IFERROR(IF(Loan_Not_Paid*Values_Entered,Monthly_Payment,""), "") | F27: =IFERROR(IF(Loan_Not_Paid*Values_Entered,Principal,""), "") | G27: =IFERROR(IF(Loan_Not_Paid*Values_Entered,Interest,""), "") | H27: =IFERROR(IF(Loan_Not_Paid*Values_Entered,Ending_Balance,""), "")
B28: =IFERROR(IF(Loan_Not_Paid*Values_Entered,Payment_Number,""), "") | C28: =IFERROR(IF(Loan_Not_Paid*Values_Entered,Payment_Date,""), "") | D28: =IFERROR(IF(Loan_Not_Paid*Values_Entered,Beginning_Balance,""), "") | E28: =IFERROR(IF(Loan_Not_Paid*Values_Entered,Monthly_Payment,""), "") | F28: =IFERROR(IF(Loan_Not_Paid*Values_Entered,Principal,""), "") | G28: =IFERROR(IF(Loan_Not_Paid*Values_Entered,Interest,""), "") | H28: =IFERROR(IF(Loan_Not_Paid*Values_Entered,Ending_Balance,""), "")
B29: =IFERROR(IF(Loan_Not_Paid*Values_Entered,Payment_Number,""), "") | C29: =IFERROR(IF(Loan_Not_Paid*Values_Entered,Payment_Date,""), "") | D29: =IFERROR(IF(Loan_Not_Paid*Values_Entered,Beginning_Balance,""), "") | E29: =IFERROR(IF(Loan_Not_Paid*Values_Entered,Monthly_Payment,""), "") | F29: =IFERROR(IF(Loan_Not_Paid*Values_Entered,Principal,""), "") | G29: =IFERROR(IF(Loan_Not_Paid*Values_Entered,Interest,""), "") | H29: =IFERROR(IF(Loan_Not_Paid*Values_Entered,Ending_Balance,""), "")
B30: =IFERROR(IF(Loan_Not_Paid*Values_Entered,Payment_Number,""), "") | C30: =IFERROR(IF(Loan_Not_Paid*Values_Entered,Payment_Date,""), "") | D30: =IFERROR(IF(Loan_Not_Paid*Values_Entered,Beginning_Balance,""), "") | E30: =IFERROR(IF(Loan_Not_Paid*Values_Entered,Monthly_Payment,""), "") | F30: =IFERROR(IF(Loan_Not_Paid*Values_Entered,Principal,""), "") | G30: =IFERROR(IF(Loan_Not_Paid*Values_Entered,Interest,""), "") | H30: =IFERROR(IF(Loan_Not_Paid*Values_Entered,Ending_Balance,""), "")
B31: =IFERROR(IF(Loan_Not_Paid*Values_Entered,Payment_Number,""), "") | C31: =IFERROR(IF(Loan_Not_Paid*Values_Entered,Payment_Date,""), "") | D31: =IFERROR(IF(Loan_Not_Paid*Values_Entered,Beginning_Balance,""), "") | E31: =IFERROR(IF(Loan_Not_Paid*Values_Entered,Monthly_Payment,""), "") | F31: =IFERROR(IF(Loan_Not_Paid*Values_Entered,Principal,""), "") | G31: =IFERROR(IF(Loan_Not_Paid*Values_Entered,Interest,""), "") | H31: =IFERROR(IF(Loan_Not_Paid*Values_Entered,Ending_Balance,""), "")
B32: =IFERROR(IF(Loan_Not_Paid*Values_Entered,Payment_Number,""), "") | C32: =IFERROR(IF(Loan_Not_Paid*Values_Entered,Payment_Date,""), "") | D32: =IFERROR(IF(Loan_Not_Paid*Values_Entered,Beginning_Balance,""), "") | E32: =IFERROR(IF(Loan_Not_Paid*Values_Entered,Monthly_Payment,""), "") | F32: =IFERROR(IF(Loan_Not_Paid*Values_Entered,Principal,""), "") | G32: =IFERROR(IF(Loan_Not_Paid*Values_Entered,Interest,""), "") | H32: =IFERROR(IF(Loan_Not_Paid*Values_Entered,Ending_Balance,""), "")
B33: =IFERROR(IF(Loan_Not_Paid*Values_Entered,Payment_Number,""), "") | C33: =IFERROR(IF(Loan_Not_Paid*Values_Entered,Payment_Date,""), "") | D33: =IFERROR(IF(Loan_Not_Paid*Values_Entered,Beginning_Balance,""), "") | E33: =IFERROR(IF(Loan_Not_Paid*Values_Entered,Monthly_Payment,""), "") | F33: =IFERROR(IF(Loan_Not_Paid*Values_Entered,Principal,""), "") | G33: =IFERROR(IF(Loan_Not_Paid*Values_Entered,Interest,""), "") | H33: =IFERROR(IF(Loan_Not_Paid*Values_Entered,Ending_Balance,""), "")
B34: =IFERROR(IF(Loan_Not_Paid*Values_Entered,Payment_Number,""), "") | C34: =IFERROR(IF(Loan_Not_Paid*Values_Entered,Payment_Date,""), "") | D34: =IFERROR(IF(Loan_Not_Paid*Values_Entered,Beginning_Balance,""), "") | E34: =IFERROR(IF(Loan_Not_Paid*Values_Entered,Monthly_Payment,""), "") | F34: =IFERROR(IF(Loan_Not_Paid*Values_Entered,Principal,""), "") | G34: =IFERROR(IF(Loan_Not_Paid*Values_Entered,Interest,""), "") | H34: =IFERROR(IF(Loan_Not_Paid*Values_Entered,Ending_Balance,""), "")
B35: =IFERROR(IF(Loan_Not_Paid*Values_Entered,Payment_Number,""), "") | C35: =IFERROR(IF(Loan_Not_Paid*Values_Entered,Payment_Date,""), "") | D35: =IFERROR(IF(Loan_Not_Paid*Values_Entered,Beginning_Balance,""), "") | E35: =IFERROR(IF(Loan_Not_Paid*Values_Entered,Monthly_Payment,""), "") | F35: =IFERROR(IF(Loan_Not_Paid*Values_Entered,Principal,""), "") | G35: =IFERROR(IF(Loan_Not_Paid*Values_Entered,Interest,""), "") | H35: =IFERROR(IF(Loan_Not_Paid*Values_Entered,Ending_Balance,""), "")
B36: =IFERROR(IF(Loan_Not_Paid*Values_Entered,Payment_Number,""), "") | C36: =IFERROR(IF(Loan_Not_Paid*Values_Entered,Payment_Date,""), "") | D36: =IFERROR(IF(Loan_Not_Paid*Values_Entered,Beginning_Balance,""), "") | E36: =IFERROR(IF(Loan_Not_Paid*Values_Entered,Monthly_Payment,""), "") | F36: =IFERROR(IF(Loan_Not_Paid*Values_Entered,Principal,""), "") | G36: =IFERROR(IF(Loan_Not_Paid*Values_Entered,Interest,""), "") | H36: =IFERROR(IF(Loan_Not_Paid*Values_Entered,Ending_Balance,""), "")
B37: =IFERROR(IF(Loan_Not_Paid*Values_Entered,Payment_Number,""), "") | C37: =IFERROR(IF(Loan_Not_Paid*Values_Entered,Payment_Date,""), "") | D37: =IFERROR(IF(Loan_Not_Paid*Values_Entered,Beginning_Balance,""), "") | E37: =IFERROR(IF(Loan_Not_Paid*Values_Entered,Monthly_Payment,""), "") | F37: =IFERROR(IF(Loan_Not_Paid*Values_Entered,Principal,""), "") | G37: =IFERROR(IF(Loan_Not_Paid*Values_Entered,Interest,""), "") | H37: =IFERROR(IF(Loan_Not_Paid*Values_Entered,Ending_Balance,""), "")
B38: =IFERROR(IF(Loan_Not_Paid*Values_Entered,Payment_Number,""), "") | C38: =IFERROR(IF(Loan_Not_Paid*Values_Entered,Payment_Date,""), "") | D38: =IFERROR(IF(Loan_Not_Paid*Values_Entered,Beginning_Balance,""), "") | E38: =IFERROR(IF(Loan_Not_Paid*Values_Entered,Monthly_Payment,""), "") | F38: =IFERROR(IF(Loan_Not_Paid*Values_Entered,Principal,""), "") | G38: =IFERROR(IF(Loan_Not_Paid*Values_Entered,Interest,""), "") | H38: =IFERROR(IF(Loan_Not_Paid*Values_Entered,Ending_Balance,""), "")
... B262: =IFERROR(IF(Loan_Not_Paid*Values_Entered,Payment_Number,""), "") | C262: =IFERROR(IF(Loan_Not_Paid*Values_Entered,Payment_Date,""), "") | D262: =IFERROR(IF(Loan_Not_Paid*Values_Entered,Beginning_Balance,""), "") | E262: =IFERROR(IF(Loan_Not_Paid*Values_Entered,Monthly_Payment,""), "") | F262: =IFERROR(IF(Loan_Not_Paid*Values_Entered,Principal,""), "") | G262: =IFERROR(IF(Loan_Not_Paid*Values_Entered,Interest,""), "") | H262: =IFERROR(IF(Loan_Not_Paid*Values_Entered,Ending_Balance,""), "")

Sheet 2 Personal Survival Budget(PSB)
B3: Personal Survival Budget
B5: Name: | C5: =IF(ISBLANK(Guidance!$E$3),"",Guidance!$E$3)
B6: Company Name: | C6: =IF(ISBLANK(Guidance!$E$4),"",Guidance!$E$4)
B8: Your Personal Survival Budget (PSB) should detail your average monthly income minus all the costs and expenses you personally incur in a typical month. This is a personal budget – not a business budget – that is designed to help us determine whether or not you will be able to meet your monthly Start Up Loan repayments. - Your PSB should show PERSONAL income and expenses only, not business related items; - Your PSB should include all credit repayments (loans, credit cards etc) as part of your expenditure; - Before completing this template, you should reference your last three-months of personal bank statements to see how much you normally earn and spend; - If we have asked you for bank statements, please ensure your income & expenses align where possible (accounting for monthly averages); - Your PSB should reflect your expected expenses for the first month after you secure your Start Up Loan; - We have linked the PSB and 12-month CFF tabs so that the monthly balance of your PSB automatically appears in your CFF. - This is designed to help you see how much money you need to draw from your business as salary in the future in order to cover your personal expenses; - If your personal expenses are more than your personal income, your monthly balance will be negative. In this instance, your business will need to generate enough money to cover the shortfall. - There is a commentary box at the bottom of this PSB, which you can use to provide any further context to the information you have provided; - Do not include your SUL repayments as credit commitment, as this is to be recorded on your CFF; - Only include income that will be ongoing. For example, if you currently earn a salary but you are planning to leave your job straight away to focus on the business, do not include this income. If you are planning to keep your job ongoing, please do include your salary.
F19: Key:
G20: These cells auto-calculate - you don't need to edit these.
G21: Insert your own text/numbers into these cells as relevant.
B24: Personal income | C24: Description (as required) | E24: Monthly net income (£) | G24: Annual net income (£)
B25: Employment (net income) | C25: Base salary at Meta (£154,000 gross p.a. — net after income tax & NI) | E25: 8200 | G25: =E25*12
B26: Benefits payments | E26: 0 | G26: =E26*12
B27: Enter other | E27: 0 | G27: =E27*12
B28: Enter other | E28: 0 | G28: =E28*12
B29: Enter other | E29: 0 | G29: =E29*12
B30: Enter other | E30: 0 | G30: =E30*12
B31: Enter other | E31: 0 | G31: =E31*12
B32: Enter other | E32: 0 | G32: =E32*12
B33: Total income across all sources: | E33: =SUM(E25:E32) | G33: =SUM(G25:G32)
B35: Personal expenses | C35: Description (as required) | E35: Monthly net expenses (£) | G35: Annual net expenses (£)
B36: Rent or mortgage payments | E36: 3200 | G36: =E36*12
B37: Council tax | E37: 180 | G37: =E37*12
B38: Utilities | E38: 200 | G38: =E38*12
B39: Phone and internet | E39: 100 | G39: =E39*12
B40: TV Licence | E40: 14 | G40: =E40*12
B41: Personal and property insurance | E41: 80 | G41: =E41*12
B42: Grocery shopping | E42: 400 | G42: =E42*12
B43: Transport costs | E43: 100 | G43: =E43*12
B44: Car tax and insurance | E44: 1000 | G44: =E44*12
B45: Subscriptions | E45: 80 | G45: =E45*12
B46: Clothing | E46: 100 | G46: =E46*12
B47: Leisure and entertainment | E47: 200 | G47: =E47*12
... B56: Enter other | E56: 0 | G56: =E56*12
B57: Total expenses across all areas: | E57: =SUM(E36:E56) | G57: =SUM(G36:G56)
E59: YOUR MONTHLY BALANCE | G59: YOUR ANNUAL BALANCE
E60: =E33-E57 | G60: =G33-G57
B63: Your notes or commentary
B64: Use this space to explain any of the information you have provided in the fields above.
B65: Remain in full-time employment at Meta (base salary £154,000 p.a.) building SOLUM alongside current role. All personal expenses including mortgage (£3,200/mo) and car (£1,000/mo) covered by employment salary with £2,046/month surplus. No salary draw from SOLUM planned in Year 1. Start Up Loan repayment (~£1,108/month) fully serviceable from personal salary with no reliance on business income. Annual bonus (~£30,800) and Meta RSU vesting (~£49,000/year) provide additional financial resilience not reflected in monthly figures.

Sheet 3 Sales Assumptions(SA)
B3: Sales assumptions
B5: Name: | C5: =IF(ISBLANK(Guidance!$E$3),"",Guidance!$E$3)
B6: Company Name: | C6: =IF(ISBLANK(Guidance!$E$4),"",Guidance!$E$4)
B8: The Sales Assumptions template will help you work out your anticipated sales and cost of sales for your business for the next 12-months. This will help your Business Adviser better understand any assumptions you have made in your forecasting. - You will be asked to choose a start month for your Sales Assumptions; this should be the next month after you expect to receive the loan; - The template will ask you to list the various product(s) and/or service(s) that your business offers and there is space for up to four items to be listed. If your business has more than this, consider grouping them together; - Work through this template in the order it sets out, as each section corresponds to the one that follows; - First you will be asked to write down the sale price of each item, and how much it costs you to produce for each individual unit; - Then you will asked to estimate the number of sales you will make for each item over the 12-months following from your preferred start date. Once you have entered this information, this will be used to calculate your total anticipated sales and cost of sales for the remainder of the year; - The Sales Assumptions is linked to the CFF tab so that your total anticipated sales and cost of sales are automatically populated. If you need to make any changes, make them in the Sales Assumptions tab and the updates will appear in your CFF; - There is a commentary box at the bottom, for which you can use to explain any of your calculations, which you think will be of use to your Business Adviser
I9: Key:
J10: These cells auto-calculate - you don't need to edit these.
J11: Insert your own text/numbers into these cells as relevant.
B16: Select your starting month: | D16: June
B18: 1. Product breakdown
C20: Product / Service 1 | D20: Product / Service 2 | E20: Product / Service 3 | F20: Product / Service 4 | J20: Worked Example
B21: Product / Service name | C21: GROUND Kit (first purchase) | D21: RITUAL Kit (first purchase) | E21: Monthly Sub — GROUND | F21: Monthly Sub — RITUAL | J21: T-Shirts
B22: Sale price (per unit) | C22: 65 | D22: 85 | E22: 38 | F22: 48 | J22: 25
B23: Cost price (per unit) | C23: 20.2 | D23: 25.4 | E23: 19.8 | F23: 17.3 | J23: 12
B24: Gross Margin (per unit) | C24: =IFERROR(SUM(C22-C23)/C22,"") | D24: =IFERROR(SUM(D22-D23)/D22,"") | E24: =IFERROR(SUM(E22-E23)/E22,"") | F24: =IFERROR(SUM(F22-F23)/F22,"") | J24: =SUM(J22-J23)/J23
B26: 2. Number of sales per month
B27: *Average sales volumes per day based on 30-days per month.
B29: Month | C29: Product / Service 1 | D29: Product / Service 2 | E29: Product / Service 3 | F29: Product / Service 4 | G29: Total sales volumes per month | H29: Average sales volumes per day* | J29: Worked Example
B30: 1 | C30: 15 | D30: 10 | E30: 0 | F30: 0 | G30: =SUM(C30:F30) | H30: =SUM(G30/30) | J30: 30
B31: 2 | C31: 18 | D31: 12 | E31: 15 | F31: 10 | G31: =SUM(C31:F31) | H31: =SUM(G31/30) | J31: 28
B32: 3 | C32: 24 | D32: 16 | E32: 32 | F32: 21 | G32: =SUM(C32:F32) | H32: =SUM(G32/30) | J32: 30
B33: 4 | C33: 30 | D33: 20 | E33: 54 | F33: 36 | G33: =SUM(C33:F33) | H33: =SUM(G33/30) | J33: 45
B34: 5 | C34: 36 | D34: 24 | E34: 80 | F34: 53 | G34: =SUM(C34:F34) | H34: =SUM(G34/30) | J34: 44
B35: 6 | C35: 39 | D35: 26 | E35: 110 | F35: 73 | G35: =SUM(C35:F35) | H35: =SUM(G35/30) | J35: 46
B36: 7 | C36: 42 | D36: 28 | E36: 141 | F36: 94 | G36: =SUM(C36:F36) | H36: =SUM(G36/30) | J36: 50
B37: 8 | C37: 30 | D37: 20 | E37: 173 | F37: 115 | G37: =SUM(C37:F37) | H37: =SUM(G37/30) | J37: 48
B38: 9 | C38: 30 | D38: 20 | E38: 191 | F38: 127 | G38: =SUM(C38:F38) | H38: =SUM(G38/30) | J38: 51
B39: 10 | C39: 33 | D39: 22 | E39: 208 | F39: 138 | G39: =SUM(C39:F39) | H39: =SUM(G39/30) | J39: 55
B40: 11 | C40: 33 | D40: 22 | E40: 226 | F40: 150 | G40: =SUM(C40:F40) | H40: =SUM(G40/30) | J40: 55
B41: 12 | C41: 36 | D41: 24 | E41: 243 | F41: 162 | G41: =SUM(C41:F41) | H41: =SUM(G41/30) | J41: 60
B44: Sales (£)
B45: You do not need to edit this section; this will auto-calculate based on your responses above. *Average sales value per day is based on 30 days per month.
B47: Month | C47: Product / Service 1 | D47: Product / Service 2 | E47: Product / Service 3 | F47: Product / Service 4 | G47: Total sales value (£) per month | H47: Average sales value per day* | J47: Worked Example
B48: 1 | C48: =SUM($C$22*C30) | D48: =SUM($D$22*D30) | E48: =SUM($E$22*E30) | F48: =SUM($F$22*F30) | G48: =SUM(C48:F48) | H48: =SUM(G48/30) | J48: =SUM($J$22*J30)
B49: 2 | C49: =SUM($C$22*C31) | D49: =SUM($D$22*D31) | E49: =SUM($E$22*E31) | F49: =SUM($F$22*F31) | G49: =SUM(C49:F49) | H49: =SUM(G49/30) | J49: =SUM($J$22*J31)
B50: 3 | C50: =SUM($C$22*C32) | D50: =SUM($D$22*D32) | E50: =SUM($E$22*E32) | F50: =SUM($F$22*F32) | G50: =SUM(C50:F50) | H50: =SUM(G50/30)
B51: 4 | C51: =SUM($C$22*C33) | D51: =SUM($D$22*D33) | E51: =SUM($E$22*E33) | F51: =SUM($F$22*F33) | G51: =SUM(C51:F51) | H51: =SUM(G51/30) | J51: =SUM($J$22*J33)
B52: 5 | C52: =SUM($C$22*C34) | D52: =SUM($D$22*D34) | E52: =SUM($E$22*E34) | F52: =SUM($F$22*F34) | G52: =SUM(C52:F52) | H52: =SUM(G52/30) | J52: =SUM($J$22*J34)
B53: 6 | C53: =SUM($C$22*C35) | D53: =SUM($D$22*D35) | E53: =SUM($E$22*E35) | F53: =SUM($F$22*F35) | G53: =SUM(C53:F53) | H53: =SUM(G53/30) | J53: =SUM($J$22*J35)
B54: 7 | C54: =SUM($C$22*C36) | D54: =SUM($D$22*D36) | E54: =SUM($E$22*E36) | F54: =SUM($F$22*F36) | G54: =SUM(C54:F54) | H54: =SUM(G54/30) | J54: =SUM($J$22*J36)
B55: 8 | C55: =SUM($C$22*C37) | D55: =SUM($D$22*D37) | E55: =SUM($E$22*E37) | F55: =SUM($F$22*F37) | G55: =SUM(C55:F55) | H55: =SUM(G55/30) | J55: =SUM($J$22*J37)
...

Sheet 4 Cash Flow Forecast(CFF)
B3: 12-Month Cash Flow Forecast
B5: Name: | C5: =IF(ISBLANK(Guidance!$E$3),"",Guidance!$E$3)
B6: Company Name: | C6: =IF(ISBLANK(Guidance!$E$4),"",Guidance!$E$4)
B8: Your Cash Flow Forecast (CFF) is an estimate of the money you expect to bring in to and pay out of your business over the next 12-months. Importantly, it should reflect all of the activity you have described in your Business Plan. - Your CFF should show BUSINESS revenue and expenses only, not personal items; - Your CFF is FORWARD looking, reflecting future anticipated transactions into and out of your business; - You can input your loan amount and the term length (12-60months), which will autocalculate onto the CFF below; - You will be asked to choose a start month for your CFF; this should be the next month after you expect to receive the loan and should match up with the month you selected in your Sales Assumptions; - Remember, some of the information that you have created in your Sales Assumptions will auto-populate in your CFF tab. These cells are blue and you do not need to edit them; - Any assumptions you make regarding your cash in-flows and cash out-flows should be both realistic and supportable. If you're starting a new business, we suggest being conservative with the cash flows you enter for the early months of trading; - It's important that your CFF corresponds with all of the objectives and activities you have outlined in your Business Plan. For example, if you have detailed plans for a three-month marketing campaign in your Business Plan then the costs for running this campaign should be clearly visible in your CFF; - Your CFF is based on a future estimate and while these figures will no doubt change over that trading period, it is a good amount of time for you - and us - to see how sustainable your plans are; - There is a commentary box at the bottom, for which you can use to explain any of costings, which you think will be of use to your Business Adviser
O13: Key:
P14: These cells auto-calculate - you don't need to edit these.
P15: Insert your own text/numbers into these cells as relevant.
B18: Loan amount | C18: 25000
B19: Interest rate | C19: 0.06
B20: Loan term (months) | C20: 24
B21: Monthly repayment | C21: =IFERROR(PMT(C19/12,C20,C18)*-1,"")
B23: Select your starting month: | C23: June
E24: MONTHS
B25: Cash in-flows | C25: Description (as required) | D25: Starting point | E25: 1 | F25: 2 | G25: 3 | H25: 4 | I25: 5 | J25: 6 | K25: 7 | L25: 8 | M25: 9 | N25: 10 | O25: 11 | P25: 12 | Q25: TOTAL
B26: Total anticipated sales | D26: 0 | E26: ='3 Sales Assumptions(SA)'!G48 | F26: ='3 Sales Assumptions(SA)'!G49 | G26: ='3 Sales Assumptions(SA)'!G50 | H26: ='3 Sales Assumptions(SA)'!G51 | I26: ='3 Sales Assumptions(SA)'!G52 | J26: ='3 Sales Assumptions(SA)'!G53 | K26: ='3 Sales Assumptions(SA)'!G54 | L26: ='3 Sales Assumptions(SA)'!G55 | M26: ='3 Sales Assumptions(SA)'!G56 | N26: ='3 Sales Assumptions(SA)'!G57 | O26: ='3 Sales Assumptions(SA)'!G58 | P26: ='3 Sales Assumptions(SA)'!G59 | Q26: =SUM(D26:P26)
B27: Value of your Start Up Loan | D27: =C18 | E27: n/a | F27: n/a | G27: n/a | H27: n/a | I27: n/a | J27: n/a | K27: n/a | L27: n/a | M27: n/a | N27: n/a | O27: n/a | P27: n/a | Q27: =SUM(D27:P27)
B28: Other sources of cash or equity | D28: 0 | E28: 0 | F28: 5000 | G28: 0 | H28: 0 | I28: 0 | J28: 0 | K28: 0 | L28: 0 | M28: 0 | N28: 0 | O28: 0 | P28: 0 | Q28: =SUM(D28:P28)
B29: Existing assets for business purposes | D29: 0 | E29: 0 | F29: 0 | G29: 0 | H29: 0 | I29: 0 | J29: 0 | K29: 0 | L29: 0 | M29: 0 | N29: 0 | O29: 0 | P29: 0 | Q29: =SUM(D29:P29)
B30: Enter other | D30: 0 | E30: 0 | F30: 0 | G30: 0 | H30: 0 | I30: 0 | J30: 0 | K30: 0 | L30: 0 | M30: 0 | N30: 0 | O30: 0 | P30: 0 | Q30: =SUM(D30:P30)
B31: Enter other | D31: 0 | E31: 0 | F31: 0 | G31: 0 | H31: 0 | I31: 0 | J31: 0 | K31: 0 | L31: 0 | M31: 0 | N31: 0 | O31: 0 | P31: 0 | Q31: =SUM(D31:P31)
B32: Enter other | D32: 0 | E32: 0 | F32: 0 | G32: 0 | H32: 0 | I32: 0 | J32: 0 | K32: 0 | L32: 0 | M32: 0 | N32: 0 | O32: 0 | P32: 0 | Q32: =SUM(D32:P32)
B33: Enter other | D33: 0 | E33: 0 | F33: 0 | G33: 0 | H33: 0 | I33: 0 | J33: 0 | K33: 0 | L33: 0 | M33: 0 | N33: 0 | O33: 0 | P33: 0 | Q33: =SUM(D33:P33)
B34: Enter other | D34: 0 | E34: 0 | F34: 0 | G34: 0 | H34: 0 | I34: 0 | J34: 0 | K34: 0 | L34: 0 | M34: 0 | N34: 0 | O34: 0 | P34: 0 | Q34: =SUM(D34:P34)
B35: Enter other | D35: 0 | E35: 0 | F35: 0 | G35: 0 | H35: 0 | I35: 0 | J35: 0 | K35: 0 | L35: 0 | M35: 0 | N35: 0 | O35: 0 | P35: 0 | Q35: =SUM(D35:P35)
B36: Enter other | D36: 0 | E36: 0 | F36: 0 | G36: 0 | H36: 0 | I36: 0 | J36: 0 | K36: 0 | L36: 0 | M36: 0 | N36: 0 | O36: 0 | P36: 0 | Q36: =SUM(D36:P36)
B37: Total cash in-flows (A) | D37: =SUM(D26:D36) | E37: =SUM(E26:E36) | F37: =SUM(F26:F36) | G37: =SUM(G26:G36) | H37: =SUM(H26:H36) | I37: =SUM(I26:I36) | J37: =SUM(J26:J36) | K37: =SUM(K26:K36) | ... P37: =SUM(P26:P36) | Q37: =SUM(D37:P37)
E40: MONTHS
B41: Cash out-flows | C41: Description (as required) | D41: Starting point | E41: 1 | F41: 2 | G41: 3 | H41: 4 | I41: 5 | J41: 6 | K41: 7 | L41: 8 | M41: 9 | N41: 10 | O41: 11 | P41: 12 | Q41: TOTAL
B42: Total anticipated cost of sales | D42: 0 | E42: ='3 Sales Assumptions(SA)'!$G65 | F42: ='3 Sales Assumptions(SA)'!$G66 | G42: ='3 Sales Assumptions(SA)'!$G67 | H42: ='3 Sales Assumptions(SA)'!$G68 | I42: ='3 Sales Assumptions(SA)'!$G69 | J42: ='3 Sales Assumptions(SA)'!$G70 | K42: ='3 Sales Assumptions(SA)'!$G71 | L42: ='3 Sales Assumptions(SA)'!$G72 | M42: ='3 Sales Assumptions(SA)'!$G73 | N42: ='3 Sales Assumptions(SA)'!$G74 | O42: ='3 Sales Assumptions(SA)'!$G75 | P42: ='3 Sales Assumptions(SA)'!$G76 | Q42: =SUM(D42:P42)
B43: Existing assets for business purposes | D43: =SUM(D29) | E43: 0 | F43: 0 | G43: 0 | H43: 0 | I43: 0 | J43: 0 | K43: 0 | L43: 0 | M43: 0 | N43: 0 | O43: 0 | P43: 0 | Q43: =SUM(D43:P43)
B44: Rent or premises costs | D44: 0 | E44: 0 | F44: 0 | G44: 0 | H44: 0 | I44: 0 | J44: 0 | K44: 0 | L44: 0 | M44: 0 | N44: 0 | O44: 0 | P44: 0 | Q44: =SUM(D44:P44)
B45: Business rates for your business premises | D45: 0 | E45: 0 | F45: 0 | G45: 0 | H45: 0 | I45: 0 | J45: 0 | K45: 0 | L45: 0 | M45: 0 | N45: 0 | O45: 0 | P45: 0 | Q45: =SUM(D45:P45)
B46: Utilities (gas, electricity, water) | D46: 0 | E46: 0 | F46: 0 | G46: 0 | H46: 0 | I46: 0 | J46: 0 | K46: 0 | L46: 0 | M46: 0 | N46: 0 | O46: 0 | P46: 0 | Q46: =SUM(D46:P46)
B47: Insurance | D47: 0 | E47: 0 | F47: 0 | G47: 0 | H47: 0 | I47: 0 | J47: 0 | K47: 0 | L47: 0 | M47: 0 | N47: 0 | O47: 0 | P47: 0 | Q47: =SUM(D47:P47)
B48: Telephone and internet | D48: 0 | E48: 80 | F48: 80 | G48: 80 | H48: 80 | I48: 80 | J48: 80 | K48: 80 | L48: 80 | M48: 80 | N48: 80 | O48: 80 | P48: 80 | Q48: =SUM(D48:P48)
B49: Marketing and advertising expenses | D49: 0 | E49: 0 | F49: 0 | G49: 0 | H49: 0 | I49: 0 | J49: 0 | K49: 0 | L49: 0 | M49: 0 | N49: 0 | O49: 0 | P49: 0 | Q49: =SUM(D49:P49)
B50: Vehicle running costs | D50: 0 | E50: 0 | F50: 0 | G50: 0 | H50: 0 | I50: 0 | J50: 0 | K50: 0 | L50: 0 | M50: 0 | N50: 0 | O50: 0 | P50: 0 | Q50: =SUM(D50:P50)
B51: Equipment purchase or leasing | D51: 0 | E51: 22000 | F51: 3000 | G51: 0 | H51: 0 | I51: 0 | J51: 0 | K51: 0 | L51: 0 | M51: 0 | N51: 0 | O51: 0 | P51: 0 | Q51: =SUM(D51:P51)
B52: Postage, printing, stationery | D52: 0 | E52: 150 | F52: 150 | G52: 150 | H52: 150 | I52: 150 | J52: 150 | K52: 200 | L52: 200 | M52: 200 | N52: 200 | O52: 200 | P52: 200 | Q52: =SUM(D52:P52)
B53: Transport and delivery | D53: 0 | E53: 0 | F53: 0 | G53: 0 | H53: 0 | I53: 0 | J53: 0 | K53: 0 | L53: 0 | M53: 0 | N53: 0 | O53: 0 | P53: 0 | Q53: =SUM(D53:P53)
...

Sheet 1 Actual Cash Flows
B3: ACTUAL CASH FLOWS: SIX-MONTHS
B5: Enter your full name | I5: Key:
B6: Enter your company name | J6: These cells auto-calculate and are locked so you can't edit them.
B7: Enter date | J7: Insert your own text/numbers into these cells as relevant.
B10: Select your starting month:
E11: MONTHS
B12: Cash in-flows | C12: Description (as required) | D12: Starting point | E12: 1 | F12: 2 | G12: 3 | H12: 4 | I12: 5 | J12: 6 | K12: TOTAL
B13: Total sales revenue | D13: 0 | E13: 0 | F13: 0 | G13: 0 | H13: 0 | I13: 0 | J13: 0 | K13: =SUM(D13:J13)
B14: Sources of investment | D14: 0 | E14: 0 | F14: 0 | G14: 0 | H14: 0 | I14: 0 | J14: 0 | K14: =SUM(D14:J14)
B15: Debt-based finance | D15: 0 | E15: 0 | F15: 0 | G15: 0 | H15: 0 | I15: 0 | J15: 0 | K15: =SUM(D15:J15)
B16: Enter other | D16: 0 | E16: 0 | F16: 0 | G16: 0 | H16: 0 | I16: 0 | J16: 0 | K16: =SUM(D16:J16)
B17: Enter other | D17: 0 | E17: 0 | F17: 0 | G17: 0 | H17: 0 | I17: 0 | J17: 0 | K17: =SUM(D17:J17)
B18: Enter other | D18: 0 | E18: 0 | F18: 0 | G18: 0 | H18: 0 | I18: 0 | J18: 0 | K18: =SUM(D18:J18)
B19: Total cash in-flows (A) | D19: =SUM(D13:D18) | E19: =SUM(E13:E18) | F19: =SUM(F13:F18) | G19: =SUM(G13:G18) | H19: =SUM(H13:H18) | I19: =SUM(I13:I18) | J19: =SUM(J13:J18) | K19: =SUM(D19:J19)
E21: MONTHS
B22: Cash out-flows | C22: Description (as required) | D22: Starting point | E22: 1 | F22: 2 | G22: 3 | H22: 4 | I22: 5 | J22: 6 | K22: TOTAL
B23: Cost of sales | D23: 0 | E23: 0 | F23: 0 | G23: 0 | H23: 0 | I23: 0 | J23: 0 | K23: =SUM(D23:J23)
B24: Rent or premises costs | D24: 0 | E24: 0 | F24: 0 | G24: 0 | H24: 0 | I24: 0 | J24: 0 | K24: =SUM(D24:J24)
B25: Business rates for your business premises | D25: 0 | E25: 0 | F25: 0 | G25: 0 | H25: 0 | I25: 0 | J25: 0 | K25: =SUM(D25:J25)
B26: Utilities (gas, electricity, water) | D26: 0 | E26: 0 | F26: 0 | G26: 0 | H26: 0 | I26: 0 | J26: 0 | K26: =SUM(D26:J26)
B27: Insurance | D27: 0 | E27: 0 | F27: 0 | G27: 0 | H27: 0 | I27: 0 | J27: 0 | K27: =SUM(D27:J27)
B28: Telephone and internet | D28: 0 | E28: 0 | F28: 0 | G28: 0 | H28: 0 | I28: 0 | J28: 0 | K28: =SUM(D28:J28)
B29: Marketing and advertising expenses | D29: 0 | E29: 0 | F29: 0 | G29: 0 | H29: 0 | I29: 0 | J29: 0 | K29: =SUM(D29:J29)
B30: Vehicle running costs | D30: 0 | E30: 0 | F30: 0 | G30: 0 | H30: 0 | I30: 0 | J30: 0 | K30: =SUM(D30:J30)
B31: Equipment purchase or leasing | D31: 0 | E31: 0 | F31: 0 | G31: 0 | H31: 0 | I31: 0 | J31: 0 | K31: =SUM(D31:J31)
B32: Postage, printing, stationery | D32: 0 | E32: 0 | F32: 0 | G32: 0 | H32: 0 | I32: 0 | J32: 0 | K32: =SUM(D32:J32)
B33: Transport and delivery | D33: 0 | E33: 0 | F33: 0 | G33: 0 | H33: 0 | I33: 0 | J33: 0 | K33: =SUM(D33:J33)
B34: Professional fees (legal, accounting etc.) | D34: 0 | E34: 0 | F34: 0 | G34: 0 | H34: 0 | I34: 0 | J34: 0 | K34: =SUM(D34:J34)
B35: Your salary | D35: n/a | E35: 0 | F35: 0 | G35: 0 | H35: 0 | I35: 0 | J35: 0 | K35: =SUM(D35:J35)
B36: Staff costs | D36: 0 | E36: 0 | F36: 0 | G36: 0 | H36: 0 | I36: 0 | J36: 0 | K36: =SUM(D36:J36)
B37: Start Up Loan monthly repayment* | D37: n/a | E37: 0 | F37: =E37 | G37: =E37 | H37: =E37 | I37: =E37 | J37: =E37 | K37: =SUM(D37:J37)
B38: Enter other | D38: 0 | E38: 0 | F38: 0 | G38: 0 | H38: 0 | I38: 0 | J38: 0 | K38: =SUM(D38:J38)
B39: Enter other | D39: 0 | E39: 0 | F39: 0 | G39: 0 | H39: 0 | I39: 0 | J39: 0 | K39: =SUM(D39:J39)
B40: Enter other | D40: 0 | E40: 0 | F40: 0 | G40: 0 | H40: 0 | I40: 0 | J40: 0 | K40: =SUM(D40:J40)
B41: Enter other | D41: 0 | E41: 0 | F41: 0 | G41: 0 | H41: 0 | I41: 0 | J41: 0 | K41: =SUM(D41:J41)
B42: Enter other | D42: 0 | E42: 0 | F42: 0 | G42: 0 | H42: 0 | I42: 0 | J42: 0 | K42: =SUM(D42:J42)
B43: Total cash out-flows (B) | D43: =SUM(D23:D42) | E43: =SUM(E23:E42) | F43: =SUM(F23:F42) | G43: =SUM(G23:G42) | H43: =SUM(H23:H42) | I43: =SUM(I23:I42) | J43: =SUM(J23:J42) | K43: =SUM(D43:J43)
C45: Your net cash flow (A-B) | D45: =D19-D43 | E45: =E19-E43 | F45: =F19-F43 | G45: =G19-G43 | H45: =H19-H43 | I45: =I19-I43 | J45: =J19-J43 | K45: =K19-K43
C47: Your monthly opening business bank account balance | D47: 0 | E47: =D49 | F47: =E49 | G47: =F49 | H47: =G49 | I47: =H49 | J47: =I49 | K47: =J49
C49: Your closing cash position | D49: =D45+D47 | E49: =E45+E47 | F49: =F45+F47 | G49: =G45+G47 | H49: =H45+H47 | I49: =I45+I47 | J49: =J45+J47 | K49: =K47
...

Sheet Excel Tips
D3: Name: | E3: =IF(ISBLANK(Guidance!$E$3),"",Guidance!$E$3)
D4: Company Name: | E4: =IF(ISBLANK(Guidance!$E$4),"",Guidance!$E$4)
D5: Application Number: | E5: =IF(ISBLANK(Guidance!#REF!),"",Guidance!#REF!)
B7: Excel Tips
B9: * | C9: If you need to go to the next line in a cell or create another bullet point in the same cell, press and hold the Alt key and click the Enter key once (Control key, option key and return key for mac users). This will tab down to the next line but you will remain in the same cell. To save the changes you have made to the cell, press Enter once you are finished. Do not press Esc as this will delete your changes.
B10: * | C10: If you need to edit a cell without deleting any of the text you have already typed in, first select the cell and click in the formula bar (shown in screenshot below)
B25: * | C25: Wherever you click in the function box, that is where your curser will appear and you will be able to add text. Please see an example below.
B37: * | C37: We have tried to size the answer cells appropriately so you don't have to make any changes. If, however, the paragraph you are writing is long and the text begins to go outside of the cell boundaries, expand the formula bar by hovering over the bottom line of the formula bar until the double headed arrow appears. Click and drag the arrow down and the formular bar will be expanded as shown below. Click Enter once you have completed the paragraph.
B52: * | C52: Once you have expanded the formula bar and you are happy with the content of the cell, expand the row by clicking and dragging the row separator as shown below. Press enter to save your changes in the cell.
B63: * | C63: To view comments on the spreadsheet, click review at the top middle of the ribbon. Next, click show comments. You should be able to move through the comments by clicking next comment or previous comment.
